<?xml version="1.0" encoding="UTF-8"?>
<testng-results skipped="0" failed="2" ignored="0" total="8" passed="6">
  <reporter-output>
  </reporter-output>
  <suite name="Default suite" duration-ms="398" started-at="2022-12-02T20:48:29 CST" finished-at="2022-12-02T20:48:30 CST">
    <groups>
    </groups>
    <test name="Default test" duration-ms="398" started-at="2022-12-02T20:48:29 CST" finished-at="2022-12-02T20:48:30 CST">
      <class name="tdd.TestPizzeriaEjercicio2">
        <test-method status="PASS" signature="preConditions()[pri:0, instance:tdd.TestPizzeriaEjercicio2@1f57539]" name="preConditions" is-config="true" duration-ms="20" started-at="2022-12-02T20:48:29 CST" finished-at="2022-12-02T20:48:29 CST">
          <reporter-output>
          </reporter-output>
        </test-method> <!-- preConditions -->
        <test-method status="PASS" signature="initialConditions()[pri:0, instance:tdd.TestPizzeriaEjercicio2@1f57539]" name="initialConditions" is-config="true" duration-ms="1" started-at="2022-12-02T20:48:30 CST" finished-at="2022-12-02T20:48:30 CST">
          <reporter-output>
          </reporter-output>
        </test-method> <!-- initialConditions -->
        <test-method status="PASS" signature="verificarClienteConTarjeta()[pri:0, instance:tdd.TestPizzeriaEjercicio2@1f57539]" name="verificarClienteConTarjeta" duration-ms="18" started-at="2022-12-02T20:48:30 CST" finished-at="2022-12-02T20:48:30 CST">
          <reporter-output>
          </reporter-output>
        </test-method> <!-- verificarClienteConTarjeta -->
        <test-method status="PASS" signature="verificarClienteSinTarjeta()[pri:0, instance:tdd.TestPizzeriaEjercicio2@1f57539]" name="verificarClienteSinTarjeta" duration-ms="7" started-at="2022-12-02T20:48:30 CST" finished-at="2022-12-02T20:48:30 CST">
          <reporter-output>
          </reporter-output>
        </test-method> <!-- verificarClienteSinTarjeta -->
        <test-method status="PASS" signature="verificarGuardarCupon()[pri:0, instance:tdd.TestPizzeriaEjercicio2@1f57539]" name="verificarGuardarCupon" duration-ms="3" started-at="2022-12-02T20:48:30 CST" finished-at="2022-12-02T20:48:30 CST">
          <reporter-output>
          </reporter-output>
        </test-method> <!-- verificarGuardarCupon -->
        <test-method status="PASS" signature="verificarNoGuardarCupon()[pri:0, instance:tdd.TestPizzeriaEjercicio2@1f57539]" name="verificarNoGuardarCupon" duration-ms="14" started-at="2022-12-02T20:48:30 CST" finished-at="2022-12-02T20:48:30 CST">
          <reporter-output>
          </reporter-output>
        </test-method> <!-- verificarNoGuardarCupon -->
        <test-method status="FAIL" signature="verificarSaldoEntre100Y150()[pri:0, instance:tdd.TestPizzeriaEjercicio2@1f57539]" name="verificarSaldoEntre100Y150" duration-ms="10" started-at="2022-12-02T20:48:30 CST" finished-at="2022-12-02T20:48:30 CST">
          <exception class="java.lang.AssertionError">
            <message>
              <![CDATA[expected [Espagueti,Queso Extra] but found [error]]]>
            </message>
            <full-stacktrace>
              <![CDATA[java.lang.AssertionError: expected [Espagueti,Queso Extra] but found [error]
at org.testng.Assert.fail(Assert.java:99)
at org.testng.Assert.failNotEquals(Assert.java:1037)
at org.testng.Assert.assertEqualsImpl(Assert.java:140)
at org.testng.Assert.assertEquals(Assert.java:122)
at org.testng.Assert.assertEquals(Assert.java:629)
at org.testng.Assert.assertEquals(Assert.java:639)
at tdd.TestPizzeriaEjercicio2.verificarSaldoEntre100Y150(TestPizzeriaEjercicio2.java:54)
at sun.reflect.NativeMethodAccessorImpl.invoke0(Native Method)
at sun.reflect.NativeMethodAccessorImpl.invoke(NativeMethodAccessorImpl.java:62)
at sun.reflect.DelegatingMethodAccessorImpl.invoke(DelegatingMethodAccessorImpl.java:43)
at java.lang.reflect.Method.invoke(Method.java:498)
at org.testng.internal.MethodInvocationHelper.invokeMethod(MethodInvocationHelper.java:133)
at org.testng.internal.TestInvoker.invokeMethod(TestInvoker.java:598)
at org.testng.internal.TestInvoker.invokeTestMethod(TestInvoker.java:173)
at org.testng.internal.MethodRunner.runInSequence(MethodRunner.java:46)
at org.testng.internal.TestInvoker$MethodInvocationAgent.invoke(TestInvoker.java:824)
at org.testng.internal.TestInvoker.invokeTestMethods(TestInvoker.java:146)
at org.testng.internal.TestMethodWorker.invokeTestMethods(TestMethodWorker.java:146)
at org.testng.internal.TestMethodWorker.run(TestMethodWorker.java:128)
at java.util.ArrayList.forEach(ArrayList.java:1259)
at org.testng.TestRunner.privateRun(TestRunner.java:794)
at org.testng.TestRunner.run(TestRunner.java:596)
at org.testng.SuiteRunner.runTest(SuiteRunner.java:377)
at org.testng.SuiteRunner.runSequentially(SuiteRunner.java:371)
at org.testng.SuiteRunner.privateRun(SuiteRunner.java:332)
at org.testng.SuiteRunner.run(SuiteRunner.java:276)
at org.testng.SuiteRunnerWorker.runSuite(SuiteRunnerWorker.java:53)
at org.testng.SuiteRunnerWorker.run(SuiteRunnerWorker.java:96)
at org.testng.TestNG.runSuitesSequentially(TestNG.java:1212)
at org.testng.TestNG.runSuitesLocally(TestNG.java:1134)
at org.testng.TestNG.runSuites(TestNG.java:1063)
at org.testng.TestNG.run(TestNG.java:1031)
at org.testng.remote.AbstractRemoteTestNG.run(AbstractRemoteTestNG.java:115)
at org.testng.remote.RemoteTestNG.initAndRun(RemoteTestNG.java:251)
at org.testng.remote.RemoteTestNG.main(RemoteTestNG.java:77)
]]>
            </full-stacktrace>
          </exception> <!-- java.lang.AssertionError -->
          <reporter-output>
          </reporter-output>
        </test-method> <!-- verificarSaldoEntre100Y150 -->
        <test-method status="FAIL" signature="verificarSaldoEntre50Y100()[pri:0, instance:tdd.TestPizzeriaEjercicio2@1f57539]" name="verificarSaldoEntre50Y100" duration-ms="11" started-at="2022-12-02T20:48:30 CST" finished-at="2022-12-02T20:48:30 CST">
          <exception class="java.lang.AssertionError">
            <message>
              <![CDATA[expected [Espagueti] but found [error]]]>
            </message>
            <full-stacktrace>
              <![CDATA[java.lang.AssertionError: expected [Espagueti] but found [error]
at org.testng.Assert.fail(Assert.java:99)
at org.testng.Assert.failNotEquals(Assert.java:1037)
at org.testng.Assert.assertEqualsImpl(Assert.java:140)
at org.testng.Assert.assertEquals(Assert.java:122)
at org.testng.Assert.assertEquals(Assert.java:629)
at org.testng.Assert.assertEquals(Assert.java:639)
at tdd.TestPizzeriaEjercicio2.verificarSaldoEntre50Y100(TestPizzeriaEjercicio2.java:47)
at sun.reflect.NativeMethodAccessorImpl.invoke0(Native Method)
at sun.reflect.NativeMethodAccessorImpl.invoke(NativeMethodAccessorImpl.java:62)
at sun.reflect.DelegatingMethodAccessorImpl.invoke(DelegatingMethodAccessorImpl.java:43)
at java.lang.reflect.Method.invoke(Method.java:498)
at org.testng.internal.MethodInvocationHelper.invokeMethod(MethodInvocationHelper.java:133)
at org.testng.internal.TestInvoker.invokeMethod(TestInvoker.java:598)
at org.testng.internal.TestInvoker.invokeTestMethod(TestInvoker.java:173)
at org.testng.internal.MethodRunner.runInSequence(MethodRunner.java:46)
at org.testng.internal.TestInvoker$MethodInvocationAgent.invoke(TestInvoker.java:824)
at org.testng.internal.TestInvoker.invokeTestMethods(TestInvoker.java:146)
at org.testng.internal.TestMethodWorker.invokeTestMethods(TestMethodWorker.java:146)
at org.testng.internal.TestMethodWorker.run(TestMethodWorker.java:128)
at java.util.ArrayList.forEach(ArrayList.java:1259)
at org.testng.TestRunner.privateRun(TestRunner.java:794)
at org.testng.TestRunner.run(TestRunner.java:596)
at org.testng.SuiteRunner.runTest(SuiteRunner.java:377)
at org.testng.SuiteRunner.runSequentially(SuiteRunner.java:371)
at org.testng.SuiteRunner.privateRun(SuiteRunner.java:332)
at org.testng.SuiteRunner.run(SuiteRunner.java:276)
at org.testng.SuiteRunnerWorker.runSuite(SuiteRunnerWorker.java:53)
at org.testng.SuiteRunnerWorker.run(SuiteRunnerWorker.java:96)
at org.testng.TestNG.runSuitesSequentially(TestNG.java:1212)
at org.testng.TestNG.runSuitesLocally(TestNG.java:1134)
at org.testng.TestNG.runSuites(TestNG.java:1063)
at org.testng.TestNG.run(TestNG.java:1031)
at org.testng.remote.AbstractRemoteTestNG.run(AbstractRemoteTestNG.java:115)
at org.testng.remote.RemoteTestNG.initAndRun(RemoteTestNG.java:251)
at org.testng.remote.RemoteTestNG.main(RemoteTestNG.java:77)
]]>
            </full-stacktrace>
          </exception> <!-- java.lang.AssertionError -->
          <reporter-output>
          </reporter-output>
        </test-method> <!-- verificarSaldoEntre50Y100 -->
        <test-method status="PASS" signature="verificarSaldoMayorA150()[pri:0, instance:tdd.TestPizzeriaEjercicio2@1f57539]" name="verificarSaldoMayorA150" duration-ms="4" started-at="2022-12-02T20:48:30 CST" finished-at="2022-12-02T20:48:30 CST">
          <reporter-output>
          </reporter-output>
        </test-method> <!-- verificarSaldoMayorA150 -->
        <test-method status="PASS" signature="verificarSaldoMenorA50()[pri:0, instance:tdd.TestPizzeriaEjercicio2@1f57539]" name="verificarSaldoMenorA50" duration-ms="4" started-at="2022-12-02T20:48:30 CST" finished-at="2022-12-02T20:48:30 CST">
          <reporter-output>
          </reporter-output>
        </test-method> <!-- verificarSaldoMenorA50 -->
      </class> <!-- tdd.TestPizzeriaEjercicio2 -->
    </test> <!-- Default test -->
  </suite> <!-- Default suite -->
</testng-results>
